I'm sorry, but an uncaught exception occurred.

While running game code:
  File "game/plant encounters.rpy", line 232, in script
    if struggled:
  File "game/plant encounters.rpy", line 232, in <module>
    if struggled:
NameError: name 'struggled' is not defined

-- Full Traceback ------------------------------------------------------------

Full traceback:
  File "game/plant encounters.rpy", line 232, in script
    if struggled:
  File "C:\Users\Owner\Desktop\renpy-8.2.3-sdk\renpy\ast.py", line 1845, in execute
    if renpy.python.py_eval(condition):
  File "C:\Users\Owner\Desktop\renpy-8.2.3-sdk\renpy\python.py", line 1209, in py_eval
    return py_eval_bytecode(code, globals, locals)
  File "C:\Users\Owner\Desktop\renpy-8.2.3-sdk\renpy\python.py", line 1202, in py_eval_bytecode
    return eval(bytecode, globals, locals)
  File "game/plant encounters.rpy", line 232, in <module>
    if struggled:
NameError: name 'struggled' is not defined

Windows-10-10.0.19045 AMD64
Ren'Py 8.2.3.24061702
sporulation 0.7.4
Mon Jul  8 21:03:57 2024
